Workbook
Name ADV2MAC: #REF!
Name cafr: Actual!$C$32
Name DIFFUSION_INDEXES: #REF!
Name EXCELFILE: #REF!

Sheet Actual
A1: $ millions | C1: PIT | D1: PIT | E1: PIT | F1: PIT | G1: PIT | H1: PIT | I1: PIT | J1: PIT | K1: PIT | L1: PIT | M1: PIT | N1: PIT | O1: PIT | Q1: CIT | R1: CIT | S1: CIT | T1: CIT | U1: CIT | V1: CIT | W1: CIT | X1: CIT | Y1: CIT | Z1: CIT | AA1: CIT | AB1: CIT | AC1: CIT | AE1: Sales | AF1: Sales | AG1: Sales | AH1: Sales | AI1: Sales | AJ1: Sales | AK1: Sales | AL1: Sales | AM1: Sales | AN1: Sales | AO1: Sales | AP1: Sales | AQ1: Sales | AT1: Total | AU1: Total | AV1: Total | AW1: Total | AX1: Total | AY1: Total | AZ1: Total | BA1: Total | BB1: Total | BC1: Total | BD1: Total | BE1: Total | BF1: Total
A2: State | B2: Abbr | C2: FY 2013 | D2: FY 2014 | E2: FY 2015 | F2: FY 2016 | G2: FY 2017 | H2: FY 2018 | I2: FY 2019 | J2: FY 2020 | K2: FY 2021 | L2: FY 2022 | M2: FY 2023 | N2: FY 2024 | O2: FY 2025 | Q2: FY 2013 | R2: FY 2014 | S2: FY 2015 | T2: FY 2016 | U2: FY 2017 | V2: FY 2018 | W2: FY 2019 | X2: FY 2020 | Y2: FY 2021 | Z2: FY 2022 | AA2: FY 2023 | AB2: FY 2024 | AC2: FY 2025 | AE2: FY 2013 | AF2: FY 2014 | AG2: FY 2015 | AH2: FY 2016 | AI2: FY 2017 | AJ2: FY 2018 | AK2: FY 2019 | AL2: FY 2020 | AM2: FY 2021 | AN2: FY 2022 | AO2: FY 2023 | AP2: FY 2024 | AQ2: FY 2025 | AT2: FY 2013 | AU2: FY 2014 | AV2: FY 2015 | AW2: FY 2016 | AX2: FY 2017 | AY2: FY 2018 | AZ2: FY 2019 | BA2: FY 2020 | BB2: FY 2021 | BC2: FY 2022 | BD2: FY 2023 | BE2: FY 2024 | BF2: FY 2025
A3: Alabama | B3: AL | C3: 3452.4006 | D3: 3480.1711 | E3: 3725.2994 | F3: 3722.13 | G3: 3892.5255 | H3: 4208.4364 | I3: 4548.4707 | J3: 4657.1673 | K3: 5643.8764 | L3: 7182.5684 | M3: 7032.0939 | N3: 7267.1289 | O3: 7495.1795 | Q3: 43.989986 | R3: 65.258757 | S3: 170.85135 | T3: 56.831934 | U3: 75.499764 | V3: 96.063758 | W3: 95.856519 | X3: 96.428942 | Y3: 98.708994 | Z3: 98.997911 | AA3: 103.45026 | AB3: 103.54586 | AC3: 103.32133 | AE3: 1978.0943 | AF3: 2020.5428 | AG3: 2108.0702 | AH3: 2230.1832 | AI3: 2287.6947 | AJ3: 2419.3148 | AK3: =2013.911327+150.44723+11.251939+23.292598+111.941527+205.423028+4.118373+33.755908 -> 2554.1419 | AL3: 2682.0885 | AM3: 3012.631 | AN3: 3269.6576 | AO3: 3446.0096 | AP3: 3422.3503 | AQ3: 3519.3319 | AT3: 7390.2268 | AU3: 7474.8923 | AV3: 7929.1673 | AW3: 7893.8605 | AX3: 8202.6535 | AY3: 8693.3721 | AZ3: =(2108210346+7214724451)/1000000 -> 9322.9348 | BA3: 9634.9796 | BB3: 11153.861 | BC3: 13134.348 | BD3: 13621.779 | BE3: 14050.105 | BF3: 14470.873
A4: Alaska | B4: AK | C4: N/A | D4: N/A | E4: N/A | F4: N/A | G4: N/A | H4: N/A | I4: N/A | J4: N/A | K4: N/A | L4: N/A | M4: N/A | N4: N/A | O4: N/A | Q4: 112.48613 | R4: 99.869191 | S4: 136.22325 | T4: 90.243942 | U4: 86.547228 | V4: 119.55631 | W4: 114.83268 | X4: 102.4 | Y4: 102.8 | Z4: 112.2 | AA4: 124.4 | AB4: 177.2 | AC4: 228.7 | AE4: N/A | AF4: N/A | AG4: N/A | AH4: N/A | AI4: N/A | AJ4: N/A | AK4: N/A | AL4: N/A | AM4: N/A | AN4: N/A | AO4: N/A | AP4: N/A | AQ4: N/A | AT4: =15812.3-2386.8 -> 13425.5 | AU4: =17243.7-2518.7 -> 14725 | AV4: =8534.3-2518.7 -> 6015.6 | AW4: =5894.1-2641.9 -> 3252.2 | AX4: =12904.9-3199.6 -> 9705.3 | AY4: =12359.9-3148.3 -> 9211.6 | AZ4: =11179.4-3446.8 -> 7732.6 | BA4: =8673.7-4189.4 -> 4484.3 | BB4: =29764.6-7570.8 -> 22193.8 | BC4: =8660.6-6911.8 -> 1748.8 | BD4: =15484.1-5826.8 -> 9657.3 | BE4: =16298-6097.1 -> 10200.9 | BF4: =19153.2-6940.1 -> 12213.1 | BG4: PRELIMINARY
A5: Arizona | B5: AZ | C5: 3397.5451 | D5: 3462.382 | E5: 3761.344 | F5: 3956.9217 | G5: 4130.8987 | H5: 4543.9984 | I5: 5009.0216 | J5: 4530.4102 | K5: 6532.7029 | L5: 7530.0107 | M5: 5239.5529 | N5: 4845.7665 | O5: 5482.9504 | Q5: 662.0264 | R5: 575.18022 | S5: 663.00301 | T5: 549.6263 | U5: 368.13645 | V5: 373.0721 | W5: 514.2641 | X5: 511.88185 | Y5: 847.0208 | Z5: 1163.4689 | AA5: 1806.3114 | AB5: 1744.8217 | AC5: 1750.5472 | AE5: 3842.3713 | AF5: 3985.88 | AG5: 4190.533 | AH5: 4299.1539 | AI5: 4505.9148 | AJ5: 4787.4625 | AK5: 5096.7503 | AL5: 5391.913 | AM5: 6244.5835 | AN5: 7208.8535 | AO5: 7677.7893 | AP5: 7933.9142 | AQ5: 8151.8501 | AT5: 8369.7386 | AU5: 8525.4 | AV5: 9168.713 | AW5: 9401.766 | AX5: 9601.8679 | AY5: 10321.501 | AZ5: 11271.319 | BA5: 11065.384 | BB5: 14345.749 | BC5: 16717.738 | BD5: 15589.624 | BE5: 15452.589 | BF5: 16428.095
A6: Arkansas | B6: AR | C6: 2649.6 | D6: 2602.2 | E6: 2664.2 | F6: 2781.5 | G6: 2767.8 | H6: =3359.6-493.4 -> 2866.2 | I6: =3520-507.5 -> 3012.5 | J6: =3418.6-503.6 -> 2915 | K6: =3969.2-502.1 -> 3467.1 | L6: =4171.5-453.6 -> 3717.9 | M6: =3915.9-768.1 -> 3147.8 | N6: =3849.6-782.9 -> 3066.7 | O6: =3594.3-655 -> 2939.3 | Q6: 375.5 | R6: 371.2 | S6: 449.5 | T6: 417.8 | U6: 366.5 | V6: =406.7-42.8 -> 363.9 | W6: =570.2-62.7 -> 507.5 | X6: =482.1-49.3 -> 432.8 | Y6: =651.9-65.3 -> 586.6 | Z6: =837.2-52.4 -> 784.8 | AA6: =842.5-60.4 -> 782.1 | AB6: =744.8-136.1 -> 608.7 | AC6: =533.1-137.3 -> 395.8 | AE6: 2124.5 | AF6: 2173.1 | AG6: 2197.8 | AH6: 2290 | AI6: 2337.9 | AJ6: 2417.5 | AK6: 2465 | AL6: 2543.7 | AM6: 2883.8 | AN6: 3154.7 | AO6: 3418.4 | AP6: 3480.4 | AQ6: 3527.9 | AT6: 5026.9906 | AU6: 5022.4451 | AV6: 5250.534 | AW6: 5367.813 | AX6: 5348.7642 | AY6: 5494.9187 | AZ6: 5921.4386 | BA6: 5753.3868 | BB6: 6845.3 | BC6: 7477.4 | BD6: 7185.4 | BE6: 6900.5 | BF6: 6679.4
A7: California | B7: CA | C7: 64484 | D7: 67025 | E7: 76169 | F7: 78735 | G7: 83264 | H7: 93776 | I7: 99189 | J7: 99599 | K7: 128856 | L7: 137144 | M7: 101748.82 | N7: 115166 | O7: 130178 | Q7: 7783 | R7: 9093 | S7: 9417 | T7: 10460 | U7: 11020 | V7: 12313 | W7: 14075 | X7: 13954 | Y7: 22591 | Z7: 45128 | AA7: 36337 | AB7: 35456 | AC7: 41338 | AE7: 20482 | AF7: 22263 | AG7: 23682 | AH7: 24871 | AI7: 24874 | AJ7: 24974 | AK7: 26150 | AL7: 25509 | AM7: 29073 | AN7: 33026 | AO7: 33324 | AP7: 33339 | AQ7: 33602 | AT7: 99402 | AU7: 102998 | AV7: 113769 | AW7: 118864 | AX7: 123422 | AY7: 135494 | AZ7: 144471 | BA7: 145082 | BB7: 186810 | BC7: 223503 | BD7: 179214 | BE7: 195261 | BF7: 218506 | BG7: PRELIMINARY
A8: Colorado | B8: CO | C8: 5596.3 | D8: 5696.1 | E8: 6350.1 | F8: 6526.5 | G8: 6760.9 | H8: 7577.2 | I8: 8247 | J8: 8644.9 | K8: 9478.1 | L8: 11717.8 | M8: 10952.7 | N8: 10044.2 | O8: 9997.9 | Q8: 636.3 | R8: 720.7 | S8: 692.9 | T8: 652.3 | U8: 509.3 | V8: 781.9 | W8: 919.8 | X8: 728.3 | Y8: 1183.7 | Z8: 1568.6 | AA8: 2366.7 | AB8: 2796.6 | AC8: 2619.5 | AE8: =2211.7+242.7 -> 2454.4 | AF8: =2424.6+241.5 -> 2666.1 | AG8: =2619.2+260.3 -> 2879.5 | AH8: =2652.6+241.2 -> 2893.8 | AI8: =2727.7+259.5 -> 2987.2 | AJ8: =2926+309.9 -> 3235.9 | AK8: =3054+345.5 -> 3399.5 | AL8: =3196+210.5 -> 3406.5 | AM8: =3418.1+214.2 -> 3632.3 | AN8: =4089+232.6 -> 4321.6 | AO8: =4301.6+251.2 -> 4552.8 | AP8: =4362.6+233.2 -> 4595.8 | AQ8: =4441.1+216.6 -> 4657.7 | AT8: 8554.8 | AU8: 8974.8 | AV8: 9802.6 | AW8: 9971.4 | AX8: 10275.8 | AY8: 11723.9 | AZ8: 12564 | BA8: 12868 | BB8: 14310.1 | BC8: 17697.9 | BD8: 17998 | BE8: 17251.4 | BF8: 17181.3 | BG8: PRELIMINARY
A9: Connecticut | B9: CT | C9: 8719.2 | D9: 8718.7 | E9: 9151 | F9: 9181.6 | G9: 8988.7 | H9: 10770.1 | I9: 9640.1613 | J9: =6815.212581+2582.566122 -> 9397.7787 | K9: =7243.803612+3096.633081 -> 10340.437 | L9: =7886.242302+4245.558091 -> 12131.8 | M9: =(8317165509+2906224724)/1000000 -> 11223.39 | N9: =(8666448405+3136598180)/1000000 -> 11803.047 | O9: =(9152951035+3810979433)/1000000 -> 12963.93 | Q9: 742.5 | R9: 782.2 | S9: 814.8 | T9: 880.4 | U9: 1037.6 | V9: 920.7 | W9: 2232.9884 | X9: 2176.448 | Y9: =1153.079316+1549.716152 -> 2702.7955 | Z9: =1401.152532+2307.593662 -> 3708.7462 | AA9: =(1516587806+2048068395)/1000000 -> 3564.6562 | AB9: =(1555553020+1964651650)/1000000 -> 3520.2047 | AC9: =(1402568919+2367029366)/1000000 -> 3769.5983 | AE9: 3897 | AF9: 4100.6 | AG9: 4205.1 | AH9: 4290.9 | AI9: 4380.6 | AJ9: 4529.7 | AK9: 4708.7 | AL9: =4317.730196+400.90817 -> 4718.6384 | AM9: =4792.674985+482.892296 -> 5275.5673 | AN9: =4818.082809+703.39131 -> 5521.4741 | AO9: =(4944771608+837629589)/1000000 -> 5782.4012 | AP9: =(5003036029+844374157)/1000000 -> 5847.4102 | AQ9: =(5120521097+877806576)/1000000 -> 5998.3277 | AT9: =19405+1232.5-3733.9 -> 16903.6 | AU9: =17009.6+1255.7-1243.9 -> 17021.4 | AV9: =17282+1360.9-1241.2 -> 17401.7 | AW9: =17780.8+1352.8-1301.5 -> 17832.1 | AX9: =17703+1394.4-1325.2 -> 17772.2 | AY9: =18198.6+1630.1-1143.1 -> 18685.6 | AZ9: =19649.8+1688.2-2083.8 -> 19254.2 | BA9: =19193.5404229999-1796.754438+1516.585006 -> 18913.371 | BB9: =20531.418459-1496.315207+1777.716829 -> 20812.82 | BC9: =21990.856849-1934.869284+2000.854493 -> 22056.842 | BD9: =(22822893588-1997837468+2069405191)/1000000 -> 22894.461 | BE9: =(22716129951-2060691770+2410570593)/1000000 -> 23066.009 | BF9: =(23891247168.82-1935141828+2221018915)/1000000 -> 24177.124
A10: Delaware | B10: DE | C10: 1139.8 | D10: 1187.7 | E10: 1251.9 | F10: 1286.6 | G10: 1333.2 | H10: 1428.1955 | I10: 1527.5065 | J10: 1472.1499 | K10: 1888.4 | L10: 1909.4 | M10: 2112.9 | N10: 2216.8944 | O10: 2383.2 | Q10: 187.9 | R10: 102 | S10: 269.5 | T10: 143.3 | U10: 120.8 | V10: 89.730071 | W10: 147.84685 | X10: 116.4697 | Y10: 209.7 | Z10: 314.2 | AA10: 383.9 | AB10: 344.81503 | AC10: 371.4 | AE10: N/A | AF10: N/A | AG10: N/A | AH10: N/A | AI10: N/A | AJ10: N/A | AK10: N/A | AL10: N/A | AM10: N/A | AN10: N/A | AO10: N/A | AP10: N/A | AQ10: N/A | AT10: 3729.8 | AU10: 3572.7 | AV10: 3955.1 | AW10: 3944.8 | AX10: 4013.095 | AY10: 4392.9769 | AZ10: 4591.9214 | BA10: 4525.8094 | BB10: 5390.3 | BC10: 5829.9 | BD10: 6295.1 | BE10: 6348.925 | BF10: 6694.3
A11: Florida | B11: FL | C11: N/A | D11: N/A | E11: N/A | F11: N/A | G11: N/A | H11: N/A | I11: N/A | J11: N/A | K11: N/A | L11: N/A | M11: N/A | N11: N/A | O11: N/A | Q11: 2081 | R11: 2042.5 | S11: 2236.3 | T11: 2272.1 | U11: 2366.4 | V11: 2413 | W11: 3139.9 | X11: 2473.5 | Y11: 3395.6 | Z11: 3761.6 | AA11: 5517.2 | AB11: 6015.8 | AC11: 5808.9 | AE11: 18417.6 | AF11: 19707.7 | AG11: 21062.7 | AH11: 21998 | AI11: 22987.4 | AJ11: 24138.7 | AK11: 25385.3 | AL11: 24591.3 | AM11: 27158.1 | AN11: 34039.7 | AO11: 35800.2 | AP11: 36014 | AQ11: 36907 | AT11: 25314.6 | AU11: 26198 | AV11: 27681.1 | AW11: 28325.4 | AX11: 29594.5 | AY11: 31218.2 | AZ11: 33413.8 | BA11: 31366.2 | BB11: 36280.9 | BC11: 44035.7 | BD11: 47327.8 | BE11: 48342 | BF11: 49676
A12: Georgia | B12: GA | C12: 8772.2274 | D12: 8965.5724 | E12: 9678.524 | F12: 10439.534 | G12: 10977.73 | H12: 11643.862 | I12: 12176.943 | J12: 12408.176 | K12: 14220.906 | L12: 18286.845 | M12: 16969.072 | N12: 16018.875 | O12: 16234.724 | Q12: 797.25543 | R12: 943.80644 | S12: 1000.5364 | T12: 981.00234 | U12: 971.84071 | V12: 1004.2975 | W12: 1271.2703 | X12: 1232.9452 | Y12: 1750.7349 | Z12: 2509.6831 | AA12: 3807.5734 | AB12: 3614.9529 | AC12: 3256.1081 | AE12: 5277.2112 | AF12: 5125.5018 | AG12: 5390.3531 | AH12: 5480.1962 | AI12: 5715.9178 | AJ12: 5945.8776 | AK12: 6250.3097 | AL12: 6174.4508 | AM12: 6947.3331 | AN12: 8316.9506 | AO12: 8918.9444 | AP12: 9004.5913 | AQ12: 9344.6258 | AT12: 18295.859 | AU12: 19167.807 | AV12: 20434.743 | AW12: 22237.393 | AX12: 23268.422 | AY12: 24319.869 | AZ12: 25571.065 | BA12: 25478.916 | BB12: 28591.83 | BC12: 34934.855 | BD12: 35944.539 | BE12: 36441.732 | BF12: 37219.732
A13: Hawaii | B13: HI | C13: 1735.499 | D13: 1745.312 | E13: 1987.752 | F13: 2116.392 | G13: 2192.341 | H13: 2429.836 | I13: 2568.114 | J13: 2359.003 | K13: 3354.561 | L13: 3759.753 | M13: 3099.886 | N13: 3280.416 | O13: 3288.541 | Q13: 100.988 | R13: 87.021 | S13: 52.319 | T13: 93.036 | U13: 173.666 | V13: 131.119 | W13: 163.676 | X13: 8.407368 | Y13: 186.347 | Z13: 255.621 | AA13: 316.831 | AB13: 483.676 | AC13: 400.097 | AE13: 2944.487 | AF13: 2825.041 | AG13: 2992.707 | AH13: 3206.154 | AI13: 3239.225 | AJ13: 3395.566 | AK13: 3541.389 | AL13: 3429.459 | AM13: 3054.356 | AN13: 3978.993 | AO13: 4408.473 | AP13: 4446.125 | AQ13: 4596.199 | AT13: 5466.923 | AU13: 5370.268 | AV13: 5735.141 | AW13: 6194.356 | AX13: 6315.215 | AY13: 6796.036 | AZ13: 7141.79 | BA13: 6694.808 | BB13: 7250.261 | BC13: 9358.848 | BD13: 9200.308 | BE13: 9568.313 | BF13: 9974.161
A14: Idaho | B14: ID | C14: 1284.38 | D14: 1329.27 | E14: 1470.86 | F14: 1513.17 | G14: 1651.1956 | H14: 1828.282 | I14: 1661.13 | J14: 1905.2455 | K14: 2446.3163 | L14: 2602.647 | M14: 2148.7127 | N14: 2228.701 | O14: 2418.855 | Q14: 198.66 | R14: 188.29 | S14: 215.4 | T14: 186.87 | U14: 214.0201 | V14: 238.708 | W14: 283.163 | X14: 243.337 | Y14: 348.555 | Z14: 1039.046 | AA14: 1031.8542 | AB14: 867.482 | AC14: 890.614 | AE14: 1109.83 | AF14: 1145.73 | AG14: 1218.77 | AH14: 1303.03 | AI14: 1382.4182 | AJ14: 1490.015 | AK14: 1597.704 | AL14: 1689.376 | AM14: 2004.203 | AN14: 2305.373 | AO14: 2503.364 | AP14: 2341.957 | AQ14: 2269.097 | AT14: 2750.28 | AU14: 2815.43 | AV14: 3056.77 | AW14: 3183.694 | AX14: 3448.407 | AY14: 3731.606 | AZ14: 3734.606 | BA14: 4031.9784 | BB14: 5009.094 | BC14: 6197.267 | BD14: 5948.0488 | BE14: 5711.262 | BF14: 5866.303
A15: Illinois | B15: IL | C15: 16538 | D15: 16642 | E15: 15913 | F15: 13806 | G15: 13661 | H15: 18747 | I15: 20411 | J15: =21657-2058 -> 19599 | K15: =26350-2372 -> 23978 | L15: =29137-2696 -> 26441 | M15: =27889-2580 -> 25309 | N15: =30134-2758 -> 27376 | O15: =33154-3031 -> 30123 | Q15: 3177 | R15: 3164 | S15: 2690 | T15: 1972 | U15: 1332 | V15: 2150 | W15: 2556 | X15: =2596-370 -> 2226 | Y15: =4450-625 -> 3825 | Z15: =6831-1026 -> 5805 | AA15: =7318-1062 -> 6256 | AB15: =6525-914 -> 5611 | AC15: =5904-827 -> 5077 | AE15: 7355 | AF15: 7676 | AG15: 8030 | AH15: 8063 | AI15: 8043 | AJ15: 8256 | AK15: 8897 | AL15: 8691 | AM15: 9799 | AN15: 10984 | AO15: 11589 | AP15: 11710 | AQ15: 11794 | AT15: 34197 | AU15: 35037 | AV15: 35250 | AW15: 30479 | AX15: 29852 | AY15: 37235 | AZ15: 40088 | BA15: 38646 | BB15: 45251 | BC15: 52222 | BD15: 53672 | BE15: 54887 | BF15: 57594
A16: Indiana | B16: IN | C16: 4977.5 | D16: 4898.8 | E16: 5233 | F16: 5218.2 | G16: 5435.3 | H16: 5816.1 | I16: 6057 | J16: 5998.9 | K16: 6804.5 | L16: 8181.2 | M16: 7575.7 | N16: 8096.1 | O16: 8687.2 | Q16: 968.4 | R16: 1054.4 | S16: 1093.7 | T16: 984 | U16: 978.7 | V16: 660.4 | W16: 948.3 | X16: 848.8 | Y16: 1225.9 | Z16: 1539.5 | AA16: 1230.6 | AB16: 965.1 | AC16: 846.8 | AE16: 6795.8 | AF16: 6925.9 | AG16: 7194.8 | AH16: 7222.6 | AI16: 7489.5 | AJ16: 7662.6 | AK16: 7915 | AL16: 8042 | AM16: 9072.6 | AN16: 9991 | AO16: 10464.7 | AP16: 10369.9 | AQ16: 10633.7 | AT16: 14462.1 | AU16: 14402.2 | AV16: 14898.4 | AW16: 14819.5 | AX16: 15274.1 | AY16: 15571.3 | AZ16: 16406.2 | BA16: 16259.5 | BB16: 18521.1 | BC16: 21190.7 | BD16: 21058.2 | BE16: 21484.6 | BF16: 22228
A17: Iowa | B17: IA | C17: 4083.9 | D17: 3974.9 | E17: 4207.3 | F17: 4355.5 | G17: 4469 | H17: 4746.7 | I17: 4944 | J17: 4652 | K17: 5434.5 | L17: 5780.1 | M17: 5599.3 | N17: 4993.2 | O17: 4947.5 | Q17: 555.3 | R17: 549.6 | S17: 576.3 | T17: 520.5 | U17: 549.7 | V17: 565 | W17: 706.3 | X17: 648.7 | Y17: 983.8 | Z17: 919 | AA17: 984.1 | AB17: 890.5 | AC17: 825.1 | AE17: 2547.6 | AF17: 2642.3 | AG17: 2753 | AH17: 2810.5 | AI17: 2812.3 | AJ17: 2941.5 | AK17: 3045.5 | AL17: 3176.1 | AM17: 3512.3 | AN17: 3853.7 | AO17: 3937.1 | AP17: 4170.4 | AQ17: 4234.9 | AT17: 6768.7 | AU17: 6489 | AV17: 6819.7 | AW17: 6921.1 | AX17: 7240 | AY17: 7383.9 | AZ17: 7858.8 | BA17: 7930.6 | BB17: 8800.6 | BC17: 9803.4 | BD17: 9845.3 | BE17: 9755.8 | BF17: 8942.2
A18: Kansas | B18: KS | C18: 2931.168 | D18: 2218.239 | E18: 2277.541 | F18: 2248.936 | G18: 2304.027 | H18: 3374.42 | I18: 3755.7104 | J18: 3338.1852 | K18: 4590.261 | L18: 4836.131 | M18: 4507.0067 | N18: 4503.6154 | O18: 4675.736 | Q18: 403.397 | R18: 431.822 | S18: 457.946 | T18: 391.877 | U18: 366.094 | V18: 437.967 | W18: =(437400155+48648035)/1000000 -> 486.04819 | X18: =(384407313+46196537)/1000000 -> 430.60385 | Y18: =652.286+75.149 -> 727.435 | Z18: =806.035+62.227 -> 868.262 | AA18: =(1504575001+56944289)/1000000 -> 1561.5193 | AB18: =(1419200508+46579609)/1000000 -> 1465.7801 | AC18: =(1313558+48986)/1000 -> 1362.544 | AE18: 2524.617 | AF18: 2446.256 | AG18: 2484.953 | AH18: 2658.933 | AI18: 2670.524 | AJ18: 2748.207 | AK18: =(2335435779+431966950)/1000000 -> 2767.4027 | AL18: =(2352523422+479059756)/1000000 -> 2831.5832 | AM18: =2522.553+602.967 -> 3125.52 | AN18: 3534.436 | AO18: 3579.8481 | AP18: 3539.4831 | AQ18: 3475.46 | AT18: 6341.125 | AU18: 5653.197 | AV18: 5928.781 | AW18: 6073.463 | AX18: 6339.059 | AY18: 7298.073 | AZ18: 7368.432 | BA18: 6900.4488 | BB18: 8865.945 | BC18: 7916.045 | BD18: 9282.81 | BE18: 10139.561 | BF18: 10022.038
A19: Kentucky | B19: KY | C19: 3722.9638 | D19: 3749.2578 | E19: 4069.5006 | F19: 4282.081 | G19: 4393.8626 | H19: 4603.5788 | I19: 4544.6762 | J19: 4765.2355 | K19: 5143.8 | L19: 6047.5 | M19: 5843.9 | N19: 5807.4991 | O19: 5319.2 | Q19: =400.752175+246.1 -> 646.85217 | R19: =475.120319+199.3 -> 674.42032 | S19: =528.118737+223.8 -> 751.91874 | T19: =526.63787+203 -> 729.63787 | U19: =497.479037+245.6 -> 743.07904 | V19: =511.4+238.1 -> 749.5 | W19: =556+206.7 -> 762.7 | X19: =346.4+292.8 -> 639.2 | Y19: 882.8 | Z19: 1186.6 | AA19: 1221.6 | AB19: 1249.1 | AC19: 1834.5 | AE19: 3021.7944 | AF19: 3131.1269 | AG19: 3267.331 | AH19: 3462.7041 | AI19: 3485.2153 | AJ19: 3605.6613 | AK19: 3937.61 | AL19: 4070.9056 | AM19: 4561 | AN19: 5062.9 | AO19: 5576.3 | AP19: 5802.5822 | AQ19: 5821.3 | AT19: 9348.326 | AU19: 9462.035 | AV19: 9966.6309 | AW19: 10338.885 | AX19: 10477.849 | AY19: 10838.2 | AZ19: 11392.698 | BA19: 11566.622 | BB19: 12827.4 | BC19: 14702.5 | BD19: 15147.7 | BE19: 15571.259 | BF19: 15703.2
A20: Louisiana | B20: LA | C20: 2753.8 | D20: 2750.6 | E20: 2886.1 | F20: 2877.8 | G20: 2959.5 | H20: 3268.6 | I20: 3719.4 | J20: 3780.3 | K20: 3956.6 | L20: 4556.1 | M20: 4654.6 | N20: 4797.9 | O20: 4768.2 | Q20: 336.3 | R20: 329.5 | S20: 300.1 | T20: 248.8 | U20: 388.4 | V20: 477.6 | W20: 630.5 | X20: 578.5 | Y20: 805.4 | Z20: 1402.1 | AA20: 1616.8 | AB20: 1636 | AC20: 1451.9 | AE20: 2581.9 | AF20: 2620.1 | AG20: 2700.8 | AH20: 2937.6 | AI20: 3827.2 | AJ20: 3892.1 | AK20: 3459.8 | AL20: 3313.7 | AM20: 3653.1 | AN20: 4406.4 | AO20: 4445 | AP20: 4482.4 | AQ20: 4869.5 | AT20: 10233.1 | AU20: 10300.1 | AV20: 10468.4 | AW20: 10400.4 | AX20: 11935.6 | AY20: 12373.2 | AZ20: 12639.9 | BA20: 12242.8 | BB20: 13232.6 | BC20: 15602.4 | BD20: 16656.9 | BE20: 17105.3 | BF20: 16785
A21: Maine | B21: ME | C21: 1521.8628 | D21: 1406.1177 | E21: 1521.7784 | F21: 1542.6876 | G21: 1523.853 | H21: 1595.1918 | I21: 1701.0058 | J21: 1835.9728 | K21: 2069.7152 | L21: 2580.6797 | M21: 2473.4789 | N21: 2388.9911 | O21: 2723.9713 | Q21: 171.98707 | R21: 182.92818 | S21: 168.96582 | T21: 137.49244 | U21: 175.23911 | V21: 185.73707 | W21: 252.86688 | X21: 216.13149 | Y21: 284.31677 | Z21: 415.81744 | AA21: 451.21106 | AB21: 459.75287 | AC21: 410.11827 | AE21: 986.74764 | AF21: 1106.1582 | AG21: 1195.0313 | AH21: 1274.145 | AI21: 1336.9448 | AJ21: 1423.5511 | AK21: 1503.7718 | AL21: 1555.7131 | AM21: 1804.2261 | AN21: 2078.8757 | AO21: 2173.0458 | AP21: 2262.2337 | AQ21: 2313.9057 | AT21: 3094.3838 | AU21: 3113.4969 | AV21: 3329.3265 | AW21: 3366.1911 | AX21: 3454.9039 | AY21: 3587.6758 | AZ21: 3848.5111 | BA21: 3969.3437 | BB21: 4520.5911 | BC21: 5391.6136 | BD21: 5379.492 | BE21: 5352.7627 | BF21: 5722.4058
A22: Maryland | B22: MD | C22: 7691.381 | D22: 7773.773 | E22: 8346.145 | F22: 8517.585 | G22: 9019.278 | H22: 9507.776 | I22: 10272.352 | J22: 10698.875 | K22: 11704.777 | L22: 13548.045 | M22: 13469.498 | N22: 13616.685 | O22: 14565.248 | Q22: 818.221 | R22: 761.208 | S22: 777.321 | T22: 874.465 | U22: 795.594 | V22: 820.401 | W22: 1033.109 | X22: 1051.8082 | Y22: 1461.893 | Z22: 1700.268 | AA22: 1816.002 | AB22: 1903.9572 | AC22: 1876.709 | AE22: 4067.791 | AF22: 4143.174 | AG22: 4350.726 | AH22: 4444.481 | AI22: 4539.32 | AJ22: 4645.756 | AK22: 4812.09 | AL22: 4634.8736 | AM22: 4988.078 | AN22: 5966.843 | AO22: 6005.249 | AP22: 5896.6057 | AQ22: 6048.565 | AT22: 14867.527 | AU22: 15016.983 | AV22: 15778.374 | AW22: 16082.63 | AX22: 16588.505 | AY22: 17311.127 | AZ22: 18399.039 | BA22: 18634.105 | BB22: 20831.014 | BC22: 24044.529 | BD22: 23672.681 | BE22: 24862.789 | BF22: 25715.684
A23: Massachusetts | B23: MA | C23: 12831 | D23: 13202 | E23: 14449 | F23: 14394 | G23: 14684 | H23: 16240 | I23: 17099 | J23: 17361 | K23: 19593 | L23: 24337 | M23: 21781 | N23: 24117 | O23: 26712 | Q23: 2262 | R23: 2510 | S23: 2561 | T23: 2548 | U23: 2497 | V23: 2761 | W23: 3308 | X23: 2924 | Y23: 4116 | Z23: 5069 | AA23: 5065 | AB23: 4833 | AC23: 4668 | AE23: 5164 | AF23: 5496 | AG23: 5774 | AH23: 6055 | AI23: 6211 | AJ23: 6454 | AK23: 6798 | AL23: 6810 | AM23: 7834 | AN23: 8765 | AO23: 9396 | AP23: 9323 | AQ23: 9599 | AT23: 22123 | AU23: 23369 | AV23: 24932 | AW23: 25269 | AX23: 25604 | AY23: 27776 | AZ23: 29693 | BA23: 29609 | BB23: 34137 | BC23: 41105 | BD23: 39165 | BE23: 40800 | BF23: 43705
A24: Michigan | B24: MI | C24: 8269.5 | D24: 8013.1 | E24: 8979.5 | F24: 9368.2 | G24: 9452 | H24: =7266.9+2892.9 -> 10159.8 | I24: =7252.5+2845.1 -> 10097.6 | J24: =6869.7+3093 -> 9962.7 | K24: =7713.5+3458.3 -> 11171.8 | L24: =9199+4059.8 -> 13258.8 | M24: =7762.3+3907.7 -> 11670 | N24: =8333.3+3962.5 -> 12295.8 | O24: =8447.2+4232.2 -> 12679.4 | Q24: 783.1 | R24: 906.4 | S24: 1077.7 | T24: 930.4 | U24: 1105.6 | V24: 1019.9 | W24: 1278.1 | X24: 1100.1 | Y24: 1701.7 | Z24: 2029.3 | AA24: 1609.9 | AB24: 1574 | AC24: 1501.4 | AE24: 7480.4 | AF24: 7895.2 | AG24: 7819 | AH24: 7877.8 | AI24: 7987.4 | AJ24: =1270.9+801.1+5881.1+632.3 -> 8585.4 | AK24: =1277.3+752.5+6008.1+596.4 -> 8634.3 | AL24: =1299.8+747.5+6048.7+613 -> 8709 | AM24: =1470.7+1255.5+6857.6+876.1 -> 10459.9 | AN24: =1694.4+1194.9+7865.1+859.4 -> 11613.8 | AO24: =1626.5+1251.6+7806.9+909.5 -> 11594.5 | AP24: =1572.5+1188.2+7757.8+940.2 -> 11458.7 | AQ24: =1644.9+1149.5+7930.8+921.4 -> 11646.6 | AT24: =9562.5+11269.7 -> 20832.2 | AU24: =9003.4+11520.5 -> 20523.9 | AV24: =10034.3+11747.1 -> 21781.4 | AW24: =10024.5+12118.7 -> 22143.2 | AX24: =10195.4+12685.2 -> 22880.6 | AY24: =11017.1+13302 -> 24319.1 | AZ24: =11115.8+13552.3 -> 24668.1 | BA24: =10775.5+13990.6 -> 24766.1 | BB24: =13009.5+16056.5 -> 29066 | BC24: =15212+17882.6 -> 33094.6 | BD24: =13966.4+17859.9 -> 31826.3 | BE24: =14527.1+18074.5 -> 32601.6 | BF24: =14480.9+18712.8 -> 33193.7
A25: Minnesota | B25: MN | C25: 9013 | D25: 9660 | E25: 10403 | F25: 10739 | G25: 10931 | H25: 11841 | I25: 12444 | J25: 12135 | K25: 14233 | L25: 16873 | M25: 15777.561 | N25: 14873.104 | O25: 16656 | Q25: 1281 | R25: 1278 | S25: 1455 | T25: 1473 | U25: 1205 | V25: 1257 | W25: 1621 | X25: 1539 | Y25: 2258 | Z25: 2823 | AA25: 2928.921 | AB25: 3171 | AC25: 3192 | AE25: 4760 | AF25: 5043 | AG25: 5131 | AH25: 5233 | AI25: 5405 | AJ25: 5453 | AK25: 5762 | AL25: 5746 | AM25: 6169 | AN25: 6644 | AO25: 7446.443 | AP25: 7546 | AQ25: 7436 | AT25: =17147+798 -> 17945 | AU25: =18554+721 -> 19275 | AV25: =19587+753 -> 20340 | AW25: =20110+779 -> 20889 | AX25: =20233+819 -> 21052 | AY25: =21248+814 -> 22062 | AZ25: =22600+879 -> 23479 | BA25: =22077+817 -> 22894 | BB25: =25660+922 -> 26582 | BC25: =29390+927 -> 30317 | BD25: =29139+1346 -> 30485 | BE25: =28562+1747 -> 30309 | BF25: =30365+1616 -> 31981
A26: Mississippi | B26: MS | C26: 1650.1 | D26: 1666.8 | E26: 1743.4 | F26: 1769.4 | G26: 1781.7 | H26: 1826.6 | I26: 1898.0593 | J26: 1819.6103 | K26: 2226.2 | L26: 2499.6 | M26: 2388.3697 | N26: 2246.5463 | O26: 2281.2244 | Q26: 524.1 | R26: 677 | S26: 714.1 | T26: 596.3 | U26: 564 | V26: 572.3 | W26: 643.65377 | X26: 548.72883 | Y26: 845.1 | Z26: 854.6 | AA26: 1037.2239 | AB26: 967.75673 | AC26: 735.24867 | AE26: 2144.6 | AF26: 2201.4 | AG26: 2260.8 | AH26: 2300.4 | AI26: 2289.3 | AJ26: 2340.4 | AK26: =(2138037754+326412860)/1000000 -> 2464.4506 | AL26: =2156.1+339.9 -> 2496 | AM26: =2244.4+408.8 -> 2653.2 | AN26: =2553.65323+428.957748 -> 2982.611 | AO26: =2734.066955+388.99789 -> 3123.0648 | AP26: =2815.901977+407.942563 -> 3223.8445 | AQ26: =2865.863821+439.92553 -> 3305.7894 | AT26: 5118.6 | AU26: 5403 | AV26: 5536.5 | AW26: 5686.7 | AX26: 5653.9 | AY26: 5691.8 | AZ26: 5967.8 | BA26: 5817.1 | BB26: 6741.3 | BC26: 7386.7 | BD26: 7694.1021 | BE26: 7707.1054 | BF26: 7642.7386
A27: Missouri | B27: MO | C27: 6367.9711 | D27: 6352.5192 | E27: 6890.8156 | F27: 7158.2409 | G27: 7320.5998 | H27: 7728.4791 | I27: 7646.9414 | J27: 6952.2002 | K27: 8916.2318 | L27: 9971.4964 | M27: 9984.7431 | N27: =9048.94027599+746.4212 -> 9795.3615 | O27: =(9165090388+718611242)/1000000 -> 9883.7016 | Q27: 525.67899 | R27: 540.71551 | S27: 558.62913 | T27: 468.28902 | U27: 435.09775 | V27: 461.7124 | W27: 526.56631 | X27: 463.1309 | Y27: 797.10995 | Z27: 909.67161 | AA27: 1058.8398 | AB27: 1050.7103 | AC27: 994.17233 | AE27: 1897.5434 | AF27: 1969.3863 | AG27: 2014.3631 | AH27: 2102.6337 | AI27: 2147.1411 | AJ27: 2196.6737 | AK27: 2237.1496 | AL27: 2276.3901 | AM27: 2428.8572 | AN27: 2746.8829 | AO27: 2943.6498 | AP27: 3184.1043 | AQ27: 3223.3634 | AT27: 8082.6866 | AU27: 8003.2897 | AV27: 8709.1671 | AW27: 8786.7731 | AX27: 9016.2418 | AY27: 9468.5807 | AZ27: 9567.3559 | BA27: 8933.5196 | BB27: 11239.918 | BC27: 12881.027 | BD27: 13234.563 | BE27: 13429.144 | BF27: 13430.979
A28: Montana | B28: MT | C28: 1047.79 | D28: 1063.284 | E28: 1175.745 | F28: 1184.8278 | G28: 1168.225 | H28: 1297.777 | I28: 1429.01 | J28: 1435.24 | K28: 1765.4 | L28: 2393.807 | M28: 2254.3051 | N28: 2243.9463 | O28: 2329.58 | Q28: 177.497 | R28: 147.548 | S28: 172.729 | T28: 118.387 | U28: 133.992 | V28: 167.1 | W28: 186.536 | X28: 187.358 | Y28: 266.5 | Z28: 293.683 | AA28: 309.88362 | AB28: 312.27636 | AC28: 321.208 | AE28: N/A | AF28: N/A | AG28: N/A | AH28: N/A | AI28: N/A | AJ28: N/A | AK28: N/A | AL28: N/A | AM28: N/A | AN28: N/A | AO28: N/A | AP28: N/A | AQ28: N/A | AT28: 2078 | AU28: 2077.044 | AV28: 2200 | AW28: 2121 | AX28: 2141 | AY28: 2405.447 | AZ28: 2572.629 | BA28: 2533.321 | BB28: 2963.8467 | BC28: 3891.6402 | BD28: 3687.7434 | BE28: 3916.9224 | BF28: 4034.369
A29: Nebraska | B29: NE | C29: 2101.912 | D29: 2060.7589 | E29: 2205.4639 | F29: 2221.0888 | G29: 2224.8401 | H29: 2360.5959 | I29: 2545.68 | J29: 2445.6475 | K29: 3130.5993 | L29: 3243.2376 | M29: 3005.9521 | N29: 2479.0542 | O29: 2179.9339 | Q29: 275.56299 | R29: 306.59103 | S29: 346.47738 | T29: 307.66969 | U29: 264.43971 | V29: 313.68952 | W29: 423.73757 | X29: 391.16375 | Y29: 571.22032 | Z29: 715.15274 | AA29: 692.96473 | AB29: 1724.9081 | AC29: 1075.0851 | AE29: 1474.9426 | AF29: 1524.7938 | AG29: 1535.4195 | AH29: 1528.0233 | AI29: 1548.3888 | AJ29: 1602.7374 | AK29: 1658.1071 | AL29: 1848.236 | AM29: 2009.7483 | AN29: 2133.1521 | AO29: 2335.8999 | AP29: 2458.8341 | AQ29: 2516.7442 | AT29: 4052.3586 | AU29: 4117.4082 | AV29: 4305.0993 | AW29: 4307.9813 | AX29: 4265.7719 | AY29: 4566.9958 | AZ29: 4896.3785 | BA29: 4939.7626 | BB29: 5959.0424 | BC29: 6348.9947 | BD29: 6367.9825 | BE29: 7155.8106 | BF29: 6159.0417
A30: Nevada | B30: NV | C30: N/A | D30: N/A | E30: N/A | F30: N/A | G30: N/A | H30: N/A | I30: N/A | J30: N/A | K30: N/A | L30: N/A | M30: N/A | N30: N/A | Q30: N/A | R30: N/A | S30: N/A | T30: N/A | U30: N/A | V30: N/A | W30: N/A | X30: N/A | Y30: N/A | Z30: N/A | AA30: N/A | AB30: N/A | AE30: 888.65896 | AF30: 931.31969 | AG30: 994.76497 | AH30: 1036.5492 | AI30: 1090.6954 | AJ30: 1142.7998 | AK30: 1235.1243 | AL30: 1214.7013 | AM30: 1325.814 | AN30: 1613.3418 | AO30: 1721.5439 | AP30: 1790.4336 | AT30: 3132.6018 | AU30: 3066.9464 | AV30: 3284.4827 | AW30: 3693.8428 | AX30: 3880.5062 | AY30: 4018.7115 | AZ30: 4287.5042 | BA30: 4077.2473 | BB30: 4474.3 | BC30: 5439.3351 | BD30: 5762.4808 | BE30: 6009.7865
A31: New Hampshire | B31: NH | C31: 92.974 | D31: 79.811 | E31: 96.861 | F31: 89.265 | G31: 94.287 | H31: 105.826 | I31: 114.68 | J31: 125.7 | K31: 120.7 | L31: 157.5 | M31: 147.3 | N31: 184.6 | O31: 72.7 | Q31: 551.8 | R31: 549.6 | S31: 561.7 | T31: 699.3 | U31: 637.8 | V31: 781.1 | W31: 805.6 | X31: 709.8 | Y31: 1003.2 | Z31: 1224 | AA31: 1258.9 | AB31: 1225.7 | AC31: 1095.6 | AE31: N/A | AF31: N/A | AG31: N/A | AH31: N/A | AI31: N/A | AJ31: N/A | AK31: N/A | AL31: N/A | AM31: N/A | AN31: N/A | AO31: N/A | AP31: N/A | AQ31: N/A | AT31: 2275.6 | AU31: 2173.2 | AV31: 2266.7 | AW31: 2457.6 | AX31: 2407.5 | AY31: 2577.2 | AZ31: 2644.6 | BA31: 2520.2 | BB31: 2979.7 | BC31: 3234.4 | BD31: 3218.5 | BE31: 3332 | BF31: 3101.1
A32: New Jersey | B32: NJ | C32: 12108.6 | D32: 12311.7 | E32: 13250 | F32: 13355.992 | G32: 13958.119 | H32: 15037.844 | I32: 15903.3 | J32: 16253.7 | K32: 17469.9 | L32: 20737.5 | M32: 18798.701 | N32: 18880.484 | Q32: 2364 | R32: 2101 | S32: 2655 | T32: 2295.378 | U32: 2141.508 | V32: 2315.529 | W32: 4029 | X32: 3807.9344 | Y32: 4884.5 | Z32: 5705.2811 | AA32: 5512.7339 | AB32: 4703.4641 | AE32: 8235 | AF32: 8640 | AG32: 8875 | AH32: 9203.341 | AI32: 9448.39 | AJ32: 9619.151 | AK32: 9939 | AL32: 9772.1042 | AM32: 11275.5 | AN32: 12525.219 | AO32: 13079.431 | AP32: 13292.492 | AT32: 30924.1 | AU32: 31347.7 | AV32: 33097.2 | AW32: 32872.6 | AX32: 34120.9 | AY32: 35785.9 | AZ32: 38316.2 | BA32: 38013.2 | BB32: 48553 | BC32: 52653 | BD32: 52099.5 | BE32: 53087
A33: New Mexico | B33: NM | C33: 1240.9453 | D33: 1254.9396 | E33: 1339.7115 | F33: 1327.2075 | G33: 1380.6752 | H33: 1519 | I33: 1672 | J33: 1691.9 | K33: 1904.1 | L33: 2327.6 | M33: 2514.7 | N33: 2207.6 | O33: 2143.1 | Q33: 267.15697 | R33: 196.76188 | S33: 254.47678 | T33: 118.50192 | U33: 70.155693 | V33: 106.6 | W33: 122.8 | X33: 63.2 | Y33: 149.7 | Z33: 343.9 | AA33: 439.1 | AB33: 627.2 | AC33: 782.5 | AE33: 1968.5711 | AF33: 2070.4043 | AG33: 2166.9929 | AH33: 2022.2974 | AI33: 2062.0775 | AJ33: 2437.2 | AK33: 2737.7 | AL33: 3005.7 | AM33: 2914.2 | AN33: 3491 | AO33: 4045.2 | AP33: 4131.8 | AQ33: 4383.5 | AT33: 5708.6 | AU33: 6040.5 | AV33: 6235.9 | AW33: 5712.1 | AX33: 6461.6 | AY33: 6881.3 | AZ33: 7910.3 | BA33: 8182.2 | BB33: 8051 | BC33: 8772.5 | BD33: 10890.1 | BE33: 13190 | BF33: 13624.1
A34: New York | B34: NY | C34: 40227 | D34: 42961 | E34: 43709 | F34: 47055 | G34: 47565 | H34: 51501 | I34: 48088 | J34: 53660 | K34: 54967 | L34: 70737 | M34: 58776 | N34: 53839 | O34: 61201 | Q34: 8465 | R34: 8259 | S34: 8504 | T34: 7884 | U34: 6979 | V34: 7164 | W34: 7912 | X34: 8995 | Y34: 8792 | Z34: 27725 | AA34: 28617 | AB34: 27695 | AC34: 31373 | AE34: 14615 | AF34: 15099 | AG34: 15384 | AH34: 15725 | AI34: 16212 | AJ34: 16711 | AK34: 17357 | AL34: 18023 | AM34: 16117 | AN34: 19621 | AO34: 20585 | AP34: 21865 | AQ34: 22352 | AT34: =66302+24036 -> 90338 | AU34: =69690+24234 -> 93924 | AV34: =71034+29438 -> 100472 | AW34: =74673+27268 -> 101941 | AX34: =74372+26594 -> 100966 | AY34: =79266+27262 -> 106528 | AZ34: =75578+31184 -> 106762 | BA34: =82889+29466 -> 112355 | BB34: =191300-78152 -> 113148 | BC34: =244375-95307 -> 149068 | BD34: =233062-89563 -> 143499 | BE34: =234478-94276 -> 140202 | BF34: =248986-96713 -> 152273
A35: North Carolina | B35: NC | C35: 10953.14 | D35: 10272.4 | E35: 11078.5 | F35: 11905.2 | G35: 11969.7 | H35: 12517.5 | I35: 13166 | J35: 12414.7 | K35: 15822.6 | L35: 17567.6 | M35: 16762.5 | N35: 16562.9 | O35: 17012.2 | Q35: =1191.7+660.1 -> 1851.8 | R35: =1356.9+697 -> 2053.9 | S35: =1327.7+544.1 -> 1871.8 | T35: =1058.2+524.4 -> 1582.6 | U35: =752.2+748.1 -> 1500.3 | V35: =739+669 -> 1408 | W35: =830.5+749.6 -> 1580.1 | X35: =657.8+646 -> 1303.8 | Y35: =1511.5+869.8 -> 2381.3 | Z35: =1625.8+888.3 -> 2514.1 | AA35: =1635+848 -> 2483 | AB35: =1552.2+741.4 -> 2293.6 | AC35: =1569.7+ 775 -> 2344.7 | AE35: 5294.2 | AF35: 5566.5 | AG35: 6252 | AH35: 6559.5 | AI35: 7004 | AJ35: 7337.4 | AK35: 7751.3 | AL35: 7820.6 | AM35: 9023.6 | AN35: 10200.7 | AO35: 10801.2 | AP35: 10905.8 | AQ35: 11006.2 | AT35: 20540.5 | AU35: 20152.7 | AV35: 21448 | AW35: 22150.7 | AX35: 22614.1 | AY35: 23565.2 | AZ35: 24826.7 | BA35: 23939.3 | BB35: 29698.9 | BC35: 33208.6 | BD35: 33535.4 | BE35: 33693.8 | BF35: 34559
A36: North Dakota | B36: ND | C36: 616.16522 | D36: 514.4322 | E36: 535.63037 | F36: 353.93775 | G36: 312.72192 | H36: 364.25412 | I36: 413.80077 | J36: 352.0966 | K36: 465.45726 | L36: 455.99017 | M36: 482.78239 | N36: 355.00178 | O36: 453.20509 | Q36: 187.06748 | R36: 239.40425 | S36: 195.83881 | T36: 97.5808 | U36: 69.225591 | V36: 92.34817 | W36: 147.75845 | X36: 91.564033 | Y36: 146.84595 | Z36: 213.43463 | AA36: 308.26094 | AB36: 276.65747 | AC36: 330.59823 | AE36: 1165.5358 | AF36: 1212.4601 | AG36: 1265.7867 | AH36: 925.36957 | AI36: 792.49826 | AJ36: 829.12021 | AK36: 957.35951 | AL36: 970.55956 | AM36: 853.43221 | AN36: 976.11374 | AO36: 1154.5302 | AP36: 1200.1614 | AQ36: 1253.7592 | AT36: 2635.5788 | AU36: 2927.3514 | AV36: 2874.4461 | AW36: 2540.2247 | AX36: 2408.9807 | AY36: 2348.6378 | AZ36: 2564.8109 | BA36: 2549.8917 | BB36: 3202.0126 | BC36: 2595.2889 | BD36: 2724.553 | BE36: 3012.5148 | BF36: 2625.7071
A37: Ohio | B37: OH | C37: 9507.83 | D37: 8064.9 | E37: 8506.7 | F37: 7799.3 | G37: 7606.5 | H37: 8411 | I37: 8910.2 | J37: 7881.3 | K37: 10201.3 | L37: 10752.2 | M37: 10797.208 | N37: 9519.3 | O37: 10461.519 | Q37: 261.9 | R37: 197.8 | S37: 182.1 | T37: 213.5 | U37: 187.3 | V37: 201.1 | W37: 202.4 | X37: 214.9 | Y37: 226.4 | Z37: 202.8 | AA37: 239.236 | AB37: 204.9 | AC37: 200.586 | AE37: 8444.85 | AF37: 9165.8 | AG37: 9960.2 | AH37: 10348 | AI37: 10614.6 | AJ37: 10148.1 | AK37: 10573.4 | AL37: 10685.7 | AM37: 12190.6 | AN37: 13029.6 | AO37: 13483.137 | AP37: 13700.5 | AQ37: 14144.774 | AT37: 21015.71 | AU37: 20134.7 | AV37: 21405.8 | AW37: 21821.6 | AX37: 21885.8 | AY37: 22423.2 | AZ37: 23489.6 | BA37: 22623 | BB37: 26467 | BC37: 28152.5 | BD37: 28915.687 | BE37: 27944.5 | BF37: 29220.222
A38: Oklahoma | B38: OK | C38: 2056.7675 | D38: 2027.9756 | E38: 2160.7781 | F38: 1989.6995 | G38: 1881.4768 | H38: 2083.7582 | I38: 2272.8898 | J38: 2434.1341 | K38: 2816.6953 | L38: 3149.1817 | M38: 3372.6309 | N38: 3253.4388 | O38: 3518.7149 | Q38: 451.63982 | R38: 306.53686 | S38: 303.45696 | T38: 259.88297 | U38: 130.621 | V38: 192.84089 | W38: 241.89665 | X38: 238.25998 | Y38: 452.13785 | Z38: 527.11497 | AA38: 598.49755 | AB38: 331.79365 | AC38: 481.65537 | AE38: =1900.847138+186.590009 -> 2087.4371 | AF38: =1959.396264+196.693829 -> 2156.0901 | AG38: =2019.725448+204.233847 -> 2223.9593 | AH38: =1893.58564+169.697019 -> 2063.2827 | AI38: =1850.145427+188.02528 -> 2038.1707 | AJ38: =2136.000056+232.925511 -> 2368.9256 | AK38: =2136.539388+306.40179 -> 2442.9412 | AL38: =2019.904805+329.163434 -> 2349.0682 | AM38: =2196.722155+369.967042 -> 2566.6892 | AN38: =2495.226162+437.992983 -> 2933.2191 | AO38: =2629.188327+483.83612 -> 3113.0244 | AP38: =2610.353375+517.902143 -> 3128.2555 | AQ38: =2296.300534+541.472159 -> 2837.7727 | AT38: 5604.0609 | AU38: 5627.4497 | AV38: 5726.5112 | AW38: 5202.1672 | AX38: 5042.9175 | AY38: 5854.2306 | AZ38: 6859.7413 | BA38: 6266.1012 | BB38: 7006.7353 | BC38: 8493.6733 | BD38: 9104.3013 | BE38: 8466.2585 | BF38: 8745.416
A39: Oregon | B39: OR | C39: 6255.646 | D39: 6628.0213 | E39: 7292.1572 | F39: 7598.557 | G39: 8457.274 | H39: 8872.479 | I39: 9908.589 | J39: 7192.048 | K39: 12772.597 | L39: 12436.649 | M39: 13246.856 | N39: 9128.408 | O39: 13041.019 | Q39: 452.88819 | R39: 494.75937 | S39: 621.76976 | T39: 603.078 | U39: 607.658 | V39: 754.98 | W39: 926.66919 | X39: 488.294 | Y39: 1478.618 | Z39: 1538.497 | AA39: 1618.518 | AB39: 1623.083 | AC39: 1527.687 | AE39: N/A | AF39: N/A | AG39: N/A | AH39: N/A | AI39: N/A | AJ39: N/A | AK39: N/A | AL39: N/A | AM39: N/A | AN39: N/A | AO39: N/A | AP39: N/A | AQ39: N/A | AT39: 7213.0734 | AU39: 7612.1 | AV39: 8418.3 | AW39: 8713.1 | AX39: 9810 | AY39: 10244.3 | AZ39: 11541.5 | BA39: 8319.2849 | BB39: 15218.9 | BC39: 14837.7 | BD39: 15759.2 | BE39: 11878.415 | BF39: 15505.895
A40: Pennsylvania | B40: PA | C40: 11371.2 | D40: 11437.3 | E40: 12107.4 | F40: 12506 | G40: 12664.4 | H40: 13399 | I40: 14095.5 | J40: 12835 | K40: 16283.4 | L40: 18125.7 | M40: 17628.1 | N40: 17856.8 | O40: 18956.5 | Q40: 2423.4 | R40: 2501.6 | S40: 2811.5 | T40: 2842.4 | U40: 2751.5 | V40: 2879 | W40: 3397.5 | X40: 2826.9 | Y40: 4423.8 | Z40: 5323.1 | AA40: 6142.9 | AB40: 5651.5 | AC40: 4719.9 | AE40: 8893.7 | AF40: 9129.6 | AG40: 9493.1 | AH40: 9795.2 | AI40: 10005.2 | AJ40: 10381.4 | AK40: 11099.6 | AL40: 10817.8 | AM40: 12834.9 | AN40: 13915.2 | AO40: 14024.4 | AP40: 14255.9 | AQ40: 14693.2 | AT40: 28646.9 | AU40: 28607.2 | AV40: 30592.5 | AW40: 30901.7 | AX40: 31669.7 | AY40: 34566.9 | AZ40: 34857.9 | BA40: 32275.8 | BB40: 40389.4 | BC40: 48134.2 | BD40: 44917.1 | BE40: 45473.5 | BF40: 46408.4
...

Sheet Forecasts
A1: $ millions | C1: PIT | D1: PIT | E1: PIT | F1: PIT | G1: PIT | H1: PIT | I1: PIT | J1: PIT | K1: PIT | L1: PIT | M1: PIT | N1: PIT | O1: PIT | P1: PIT | Q1: PIT | S1: CIT | T1: CIT | U1: CIT | V1: CIT | W1: CIT | X1: CIT | Y1: CIT | Z1: CIT | AA1: CIT | AB1: CIT | AC1: CIT | AD1: CIT | AE1: CIT | AF1: CIT | AG1: CIT | AI1: Sales | AJ1: Sales | AK1: Sales | AL1: Sales | AM1: Sales | AN1: Sales | AO1: Sales | AP1: Sales | AQ1: Sales | AR1: Sales | AS1: Sales | AT1: Sales | AU1: Sales | AV1: Sales | AW1: Sales | AY1: Total | AZ1: Total | BA1: Total | BB1: Total | BC1: Total | BD1: Total | BE1: Total | BF1: Total | BG1: Total | BH1: Total | BI1: Total | BJ1: Total | BK1: Total | BL1: Total | BM1: Total | BO1: Forecast Date
A2: State | B2: Abbr | C2: FY 2013 | D2: FY 2014 | E2: FY 2015 | F2: FY 2016 | G2: FY 2017 | H2: FY 2018 | I2: FY 2019 | J2: FY 2020 | K2: FY 2021 | L2: FY 2022 | M2: FY 2023 | N2: FY 2024 | O2: FY 2025 | P2: FY 2026 | Q2: FY 2027 | S2: FY 2013 | T2: FY 2014 | U2: FY 2015 | V2: FY 2016 | W2: FY 2017 | X2: FY 2018 | Y2: FY 2019 | Z2: FY 2020 | AA2: FY 2021 | AB2: FY 2022 | AC2: FY 2023 | AD2: FY 2024 | AE2: FY 2025 | AF2: FY 2026 | AG2: FY 2027 | AI2: FY 2013 | AJ2: FY 2014 | AK2: FY 2015 | AL2: FY 2016 | AM2: FY 2017 | AN2: FY 2018 | AO2: FY 2019 | AP2: FY 2020 | AQ2: FY 2021 | AR2: FY 2022 | AS2: FY 2023 | AT2: FY 2024 | AU2: FY 2025 | AV2: FY 2026 | AW2: FY 2027 | AY2: FY 2013 | AZ2: FY 2014 | BA2: FY 2015 | BB2: FY 2016 | BC2: FY 2017 | BD2: FY 2018 | BE2: FY 2019 | BF2: FY 2020 | BG2: FY 2021 | BH2: FY 2022 | BI2: FY 2023 | BJ2: FY 2024 | BK2: FY 2025 | BL2: FY 2026 | BM2: FY 2027 | BO2: FY 2013 | BP2: FY 2014 | BQ2: FY 2015 | BR2: FY 2016 | BS2: FY 2017 | BT2: FY 2018 | BU2: FY 2019 | BV2: FY 2020 | BW2: FY 2021 | BX2: FY 2022 | BY2: FY 2023 | BZ2: FY 2024 | CA2: FY 2025 | CB2: FY 2026 | CC2: FY 2027 | CD2: Budget cycle
A3: Alabama | B3: AL | C3: 3281.81 | D3: 3473 | E3: 3681 | F3: 3746 | G3: 3843 | H3: 3976 | I3: 4158 | J3: 4437.1114 | K3: 4877.3017 | L3: 4777.4046 | M3: 5129.8835 | N3: 7500 | O3: 6750 | P3: 7569.7972 | S3: 44.36 | T3: 52.5 | U3: 115 | V3: 58 | W3: 75.5 | X3: 96.5 | Y3: 96 | Z3: 96 | AA3: 96 | AB3: 96 | AC3: 103 | AD3: 104.8 | AE3: 103.96488 | AF3: 108.9046 | AI3: 2089.4494 | AJ3: 2066.3 | AK3: 2094.4 | AL3: 2378.8 | AM3: 2271.6 | AN3: 2392 | AO3: 2407 | AP3: 2610.4492 | AQ3: 2749.7442 | AR3: 2839.1024 | AS3: 3182.9369 | AT3: 3474.2661 | AU3: 3465.0259 | AV3: 3585.7088 | AY3: =5719.45+1371.744 -> 7091.194 | AZ3: =(1663043840+5824593296)/1000000 -> 7487.6371 | BA3: 7841.7174 | BB3: 8298.4463 | BC3: 8041.5834 | BD3: 8364.6494 | BE3: 8599.0709 | BF3: 9215.8394 | BG3: 9927.265 | BH3: 9980.8064 | BI3: 10859.205 | BJ3: =(2823184399+10904087198)/1000000 -> 13727.272 | BK3: 13182.237 | BL3: 14404.785 | BO3: 40909 | BP3: 41275 | BQ3: 41640 | BR3: 42005 | BS3: 42370 | BT3: 42736 | BU3: 43101 | BV3: 43466 | BW3: 43831 | BX3: 44197 | BY3: 44562 | BZ3: 44927 | CA3: 45292 | CB3: 45658 | CD3: Annual
A4: Alaska | B4: AK | C4: N/A | D4: N/A | E4: N/A | F4: N/A | G4: N/A | H4: N/A | I4: N/A | J4: N/A | K4: N/A | L4: N/A | M4: N/A | N4: N/A | O4: N/A | P4: N/A | S4: 167.6 | T4: 100.5 | U4: 127.1 | V4: 125.9 | W4: 99.3 | X4: 154.9 | Y4: 145 | Z4: 135 | AA4: 75 | AB4: 10 | AC4: 125 | AD4: 125 | AE4: 160 | AF4: 235 | AI4: N/A | AJ4: N/A | AK4: N/A | AL4: N/A | AM4: N/A | AN4: N/A | AO4: N/A | AP4: N/A | AQ4: N/A | AR4: N/A | AS4: N/A | AT4: N/A | AU4: N/A | AV4: N/A | AY4: =16492.4-2862.2 -> 13630.2 | AZ4: =14622.9-2965 -> 11657.9 | BA4: =12567.5-3116.4 -> 9451.1 | BB4: =9957.6-3401.8 -> 6555.8 | BC4: =8219-3401.8 -> 4817.2 | BD4: =10188.7-3466.7 -> 6722 | BE4: =11172.3-3678.4 -> 7493.9 | BF4: =10970.6-3257.9 -> 7712.7 | BG4: =10569.9-4314 -> 6255.9 | BH4: =11040.8-4070.3 -> 6970.5 | BI4: =16435.4-5183.8 -> 11251.6 | BJ4: =14904-5433.7 -> 9470.3 | BK4: =16515.8-6472.5 -> 10043.3 | BL4: =15900.8-6080.7 -> 9820.1 | BO4: 40969 | BP4: 41334 | BQ4: 41699 | BR4: 42064 | BS4: 42430 | BT4: 42795 | BU4: 43160 | BV4: 43525 | BW4: 43891 | BX4: 44270 | BY4: 44621 | BZ4: 45006 | CA4: 45352 | CB4: 45717 | CD4: Annual
A5: Arizona | B5: AZ | C5: 3280 | D5: 3531.2579 | E5: 3868.06 | F5: 3741.4672 | G5: 4147.14 | H5: 4282.79 | I5: 4507.9 | J5: 5008.63 | K5: 5311.765 | L5: 5555.8199 | M5: 5590 | N5: 5662.2761 | O5: 5185.639 | P5: 5481.7877 | S5: 630 | T5: 714.91 | U5: 573.868 | V5: 465.0621 | W5: 563.325 | X5: 389.3901 | Y5: 299.06 | Z5: 427 | AA5: 533.98 | AB5: 533.5182 | AC5: 815.5695 | AD5: 1305.7 | AE5: 1795.146 | AF5: 1933.857 | AI5: 3900 | AJ5: 4029.02 | AK5: 4290.6 | AL5: 4343.8893 | AM5: 4502.5448 | AN5: 4676.87 | AO5: 4838.4 | AP5: 5289.43 | AQ5: 5669.9034 | AR5: 6091.9181 | AS5: 6918.59 | AT5: 7943.3568 | AU5: 8280.3115 | AV5: 8484.4251 | AY5: 8262.8 | AZ5: 8742.6405 | BA5: 9246.5752 | BB5: 9116.9486 | BC5: 9763.3108 | BD5: 9945.7321 | BE5: 10261.598 | BF5: 11330.919 | BG5: 12178.302 | BH5: 12829.764 | BI5: 14054.549 | BJ5: 15805.054 | BK5: 16126.318 | BL5: 16948.879 | BO5: 40909 | BP5: 41275 | BQ5: 41640 | BR5: 42005 | BS5: 42370 | BT5: 42736 | BU5: 43101 | BV5: 43466 | BW5: 43831 | BX5: 44197 | BY5: 44562 | BZ5: 44927 | CA5: 45292 | CB5: 45658 | CD5: Annual
A6: Arkansas | B6: AR | C6: =2888.2-507.2 -> 2381 | D6: =3101.2-541.4 -> 2559.8 | E6: =3173.4-553.5 -> 2619.9 | F6: =3092-431.3 -> 2660.7 | G6: =3220.5-479.4 -> 2741.1 | H6: =3319-522.1 -> 2796.9 | I6: =3428.8-504.6 -> 2924.2 | J6: =3578.8-581.1 -> 2997.7 | K6: =3359.1-455 -> 2904.1 | L6: =3189.7-370 -> 2819.7 | M6: =3907.1-486.4 -> 3420.7 | N6: =3586.8-558.5 -> 3028.3 | O6: =3753.6-629.1 -> 3124.5 | P6: 2947.4 | S6: =406.9-45.4 -> 361.5 | T6: =429-61.6 -> 367.4 | U6: =450.2-60.5 -> 389.7 | V6: =476.2-48 -> 428.2 | W6: =462.3-54 -> 408.3 | X6: =474.9-64.8 -> 410.1 | Y6: =482.3-70.4 -> 411.9 | Z6: =404.6-52.4 -> 352.2 | AA6: =449.4-63.1 -> 386.3 | AB6: =478.7-68.8 -> 409.9 | AC6: =642.2-71.9 -> 570.3 | AD6: =519.2-72.7 -> 446.5 | AE6: =718.3-74.3 -> 644 | AF6: 434.8 | AI6: 2174.1 | AJ6: 2207.7 | AK6: 2208 | AL6: 2273 | AM6: 2396 | AN6: 2444.9 | AO6: 2487.7 | AP6: 2572.4 | AQ6: 2569.4 | AR6: 2815.3 | AS6: 3166.8 | AT6: 3405.1 | AU6: 3547.9 | AV6: 3575.6 | AY6: 4727.5 | AZ6: 4957.6 | BA6: 5040.7 | BB6: 5186.2 | BC6: 5333.1 | BD6: 5453.2 | BE6: 5690.2 | BF6: 5737.1 | BG6: 5687.3 | BH6: 5866.2 | BI6: 6938.3 | BJ6: 6625.4 | BK6: 7075.2 | BL6: 6679.1 | BO6: 41030 | BP6: 41395 | BQ6: 41760 | BR6: 42125 | BS6: 42491 | BT6: 42856 | BU6: 43221 | BV6: 43586 | BW6: 43923 | BX6: 44335 | BY6: 44682 | BZ6: 45047 | CA6: 45413 | CB6: 45778 | CD6: Biennial (odd)
A7: California | B7: CA | C7: 60268 | D7: 60827 | E7: 70238 | F7: 77700 | G7: 83393 | H7: 88961 | I7: 95009 | J7: 102333 | K7: 76619.63 | L7: 123298 | M7: 137454 | N7: 118136 | O7: 116176 | P7: 126107 | S7: 8488 | T7: 8508 | U7: 8910 | V7: 10342 | W7: 10993 | X7: 10894 | Y7: 12248 | Z7: 13233 | AA7: 12367.49 | AB7: 18106 | AC7: 38464 | AD7: 42081 | AE7: 36778 | AF7: 35293 | AI7: 20605 | AJ7: 22983 | AK7: 23823 | AL7: 25240 | AM7: 25727 | AN7: 24470 | AO7: 26674 | AP7: 27241 | AQ7: 20570.8 | AR7: 28986 | AS7: 33991 | AT7: 33366 | AU7: 34043 | AV7: 34866 | AY7: 95689 | AZ7: 97235 | BA7: 106951 | BB7: 118031 | BC7: 124160 | BD7: 128316 | BE7: 138317 | BF7: 147833 | BG7: 119244 | BH7: 181745 | BI7: 222966 | BJ7: 206640 | BK7: 199128 | BL7: 206736 | BO7: 41030 | BP7: 41395 | BQ7: 41760 | BR7: 42125 | BS7: 42491 | BT7: 42856 | BU7: 43221 | BV7: 43586 | BW7: 43952 | BX7: 44317 | BY7: 44682 | BZ7: 45047 | CA7: 45413 | CB7: 45778 | CD7: Annual
A8: Colorado | B8: CO | C8: 5131.1 | D8: 5687.3 | E8: 6002.5 | F8: 6493.3 | G8: 6803.3 | H8: 7275.7 | I8: 7978.4 | J8: 8617.1 | K8: 6957.8 | L8: 9877.5 | M8: 11620.5 | N8: 11139 | O8: 10138.9 | P8: 10744.8 | S8: 448.5 | T8: 760.9 | U8: 804.2 | V8: 656.8 | W8: 606.8 | X8: 632.8 | Y8: 778.8 | Z8: 857.1 | AA8: 443.6 | AB8: 982.6 | AC8: 1192.5 | AD8: 1930.8 | AE8: 2226.1 | AF8: 2124.8 | AI8: =2083.2+208.8 -> 2292 | AJ8: =2320.6+244.1 -> 2564.7 | AK8: =2497+263.5 -> 2760.5 | AL8: =2807.8+288.6 -> 3096.4 | AM8: =2792.7+270.7 -> 3063.4 | AN8: =3022.3+277.5 -> 3299.8 | AO8: =3084.7+338.5 -> 3423.2 | AP8: =3223.8+314.9 -> 3538.7 | AQ8: =3089.6+202 -> 3291.6 | AR8: =3492.8+216.1 -> 3708.9 | AS8: =4221+258.3 -> 4479.3 | AT8: =4487.6+263.7 -> 4751.3 | AU8: =4508.1+240.7 -> 4748.8 | AV8: =4585.3+232.9 -> 4818.2 | AY8: 7847.3 | AZ8: 8897.6 | BA8: 9448.2 | BB8: 10089.6 | BC8: 10360.2 | BD8: 11087.5 | BE8: 12192.5 | BF8: 13029.9 | BG8: 10832.8 | BH8: 14868.4 | BI8: 17427.1 | BJ8: 17763.7 | BK8: 17010 | BL8: 17573.1 | BO8: 41061 | BP8: 41426 | BQ8: 41791 | BR8: 42156 | BS8: 42522 | BT8: 42887 | BU8: 43252 | BV8: 43617 | BW8: 43983 | BX8: 44365 | BY8: 44713 | BZ8: 45078 | CA8: 45444 | CB8: 45809 | CD8: Annual
A9: Connecticut | B9: CT | C9: 8551.3 | D9: 8796.9 | E9: 9267.5 | F9: 9665.1 | G9: 9522 | H9: 9096.7 | I9: 9707.6 | J9: =6808.6+2767.5 -> 9576.1 | K9: =6408.3+1822.3 -> 8230.6 | L9: =7321.9+2689.1 -> 10011 | M9: =8227.3+3522.7 -> 11750 | N9: =8547.5+2666.4 -> 11213.9 | O9: =8759.1+3123.5 -> 11882.6 | P9: =9287.2+3343.7 -> 12630.9 | S9: 792 | T9: 668.6 | U9: 704.3 | V9: 644.1 | W9: 839.3 | X9: 872.1 | Y9: 920.2 | Z9: =1005.4+850 -> 1855.4 | AA9: =808.6+850.7 -> 1659.3 | AB9: =1021.2+1485.8 -> 2507 | AC9: =1303.6+1957.3 -> 3260.9 | AD9: =1443.8+1815.6 -> 3259.4 | AE9: =1560.7+1969.3 -> 3530 | AF9: =1470.1+2115.3 -> 3585.4 | AI9: 4039.2 | AJ9: 3953 | AK9: 4173.4 | AL9: 4374 | AM9: 4314 | AN9: 4169.3 | AO9: 4512 | AP9: =4299.1+468.9 -> 4768 | AQ9: =3985.7+395.8 -> 4381.5 | AR9: =4234.9+665 -> 4899.9 | AS9: =4787.3+794.4 -> 5581.7 | AT9: =5301.7+860.2 -> 6161.9 | AU9: =5103.5+879.2 -> 5982.7 | AV9: =5103.5+879.2 -> 5982.7 | AY9: =19067.8+1303.8-3654.8 -> 16716.8 | AZ9: =19396.5+1333.6-4248.3 -> 16481.8 | BA9: =17403.6+1330.5-1292.1 -> 17442 | BB9: =17360.3+1500.5-1305.6 -> 17555.2 | BC9: =17750.4+1513.6-1262.7 -> 18001.3 | BD9: =17085.1+1593.5-1282.5 -> 17396.1 | BE9: =19056.6+1591.5-2167.1 -> 18481 | BF9: =18400.5+1808-1401.8 -> 18806.7 | BG9: =18088.4+1676.9-1922.8 -> 17842.5 | BH9: =19757.6+1884.7-1755.1 -> 19887.2 | BI9: =23384.2+2242.7-1962.7 -> 23664.2 | BJ9: =22790.8+2401-1827.5 -> 23364.3 | BK9: =23129.5+2410.5-1893.7 -> 23646.3 | BL9: =23782.9-1825.4+2292.1 -> 24249.6 | BO9: 41000 | BP9: 41365 | BQ9: 41730 | BR9: 42095 | BS9: 42461 | BT9: 42826 | BU9: 43191 | BV9: 43556 | BW9: 43922 | BX9: 44316 | BY9: 44652 | BZ9: 45031 | CA9: 45383 | CB9: 45748 | CD9: Biennial (odd)
A10: Delaware | B10: DE | C10: 1086.2 | D10: 1172.5 | E10: 1226.3 | F10: 1297 | G10: 1334.3 | H10: 1373.4 | I10: 1486.3 | J10: 1590.2 | K10: 1562.1 | L10: 1788.2 | M10: 2061.6 | N10: 2089.1 | O10: 2313.2 | P10: 2531.2 | S10: 176.1 | T10: 203.4 | U10: 212.4 | V10: 154 | W10: 157.4 | X10: 108.4 | Y10: 92.8 | Z10: 112.2 | AA10: 76.8 | AB10: 144.9 | AC10: 199.3 | AD10: 282.7 | AE10: 270 | AF10: 330.3 | AI10: N/A | AJ10: N/A | AK10: N/A | AL10: N/A | AM10: N/A | AN10: N/A | AO10: N/A | AP10: N/A | AQ10: N/A | AR10: N/A | AS10: N/A | AT10: N/A | AU10: N/A | AV10: N/A | AY10: 3697.1 | AZ10: 3740.6 | BA10: 3890 | BB10: 3867.8 | BC10: 4025.9 | BD10: 3997.4 | BE10: 4383.4 | BF10: 4617.3 | BG10: 4535.4 | BH10: 5124.9 | BI10: 5814.5 | BJ10: 6039.4 | BK10: 6418.3 | BL10: 6777.7 | BO10: 41061 | BP10: 41426 | BQ10: 41791 | BR10: 42156 | BS10: 42522 | BT10: 42887 | BU10: 43252 | BV10: 43617 | BW10: 43983 | BX10: 44364 | BY10: 44713 | BZ10: 45078 | CA10: 45413 | CB10: 45778 | CD10: Annual
A11: Florida | B11: FL | C11: N/A | D11: N/A | E11: N/A | F11: N/A | G11: N/A | H11: N/A | I11: N/A | J11: N/A | K11: N/A | L11: N/A | M11: N/A | N11: N/A | O11: N/A | P11: N/A | S11: 2159.1 | T11: 2283.6 | U11: 2254.8 | V11: 2208.3 | W11: 2147.4 | X11: 2339.5 | Y11: 2376.2 | Z11: 2694.6 | AA11: 2843 | AB11: 2876.3 | AC11: 3822.2 | AD11: 5482.1 | AE11: 5774.4 | AF11: 5960.9 | AI11: 18101.4 | AJ11: 19158.7 | AK11: 20463.6 | AL11: 21773 | AM11: 23217.3 | AN11: 24091.4 | AO11: 25070.2 | AP11: 26058.5 | AQ11: 27022.9 | AR11: 27134.6 | AS11: 29797.4 | AT11: 34577 | AU11: 36244.5 | AV11: 37738.9 | AY11: 24506.9 | AZ11: 26006.4 | BA11: 27140.2 | BB11: 28126.8 | BC11: 29464.7 | BD11: 30793.8 | BE11: 32256.9 | BF11: 33506.5 | BG11: 34449.3 | BH11: 34864.9 | BI11: 39041.1 | BJ11: 45300.6 | BK11: 48009.7 | BL11: 50200.6 | BO11: 40909 | BP11: 41334 | BQ11: 41710 | BR11: 42073 | BS11: 42388 | BT11: 42811 | BU11: 43140 | BV11: 43525 | BW11: 43831 | BX11: 44292 | BY11: 44562 | BZ11: 44998 | CA11: 45292 | CB11: 45717 | CD11: Annual
A12: Georgia | B12: GA | C12: 8604.798 | D12: 8895.846 | E12: 9536.657 | F12: 9839.041 | G12: 10715.557 | H12: 11454.618 | I12: 12025.913 | J12: 12754.221 | K12: 12653.107 | L12: 12738.708 | M12: 14101.898 | N12: 14706.897 | O12: 15808.929 | P12: 15693.797 | S12: 735.41372 | T12: 775.314 | U12: 846.667 | V12: 995.534 | W12: 1023.3514 | X12: 1042.83 | Y12: 1067.9791 | Z12: 1259.624 | AA12: 1536.1181 | AB12: 880.77726 | AC12: 1396.9884 | AD12: 1401.7095 | AE12: 3062.908 | AF12: 3254.3608 | AI12: 5560.6527 | AJ12: 5094.297 | AK12: 5258.817 | AL12: 5593.609 | AM12: 5658.9 | AN12: 5848.547 | AO12: 6092.7808 | AP12: 6525.181 | AQ12: 6722.1413 | AR12: 6649.0841 | AS12: 7402.3142 | AT12: 8365.6576 | AU12: 8369.25 | AV12: 9434.9741 | AY12: 18156.467 | AZ12: 18798.349 | BA12: 19726.831 | BB12: 20647.628 | BC12: 22523.214 | BD12: 23713.413 | BE12: 24679.053 | BF12: 26143.818 | BG12: 26631.766 | BH12: 25775.587 | BI12: 28634.939 | BJ12: 30784.469 | BK12: 34425.232 | BL12: 35897.957 | BO12: 40878 | BP12: 41244 | BQ12: 41609 | BR12: 41974 | BS12: 42339 | BT12: 42705 | BU12: 43070 | BV12: 43435 | BW12: 43800 | BX12: 44166 | BY12: 44531 | BZ12: 44896 | CA12: 45261 | CB12: 45627 | CD12: Annual
A13: Hawaii | B13: HI | C13: 1528.684 | D13: 1789.785 | E13: 1912.378 | F13: 1915.067 | G13: 2130.32 | H13: 2196.838 | I13: 2537.392 | J13: 2659.251 | K13: 2058.28 | L13: 2497.695 | M13: 3861.257 | N13: 3504.931 | O13: 2910.104 | P13: 3024.052 | S13: 58.943 | T13: 82.275 | U13: 69.034 | V13: 99.534 | W13: 80.713 | X13: 83.305 | Y13: 105.421 | Z13: 127.677 | AA13: 111.188 | AB13: 148.986 | AC13: 460.66 | AD13: 162.178 | AE13: 368.917 | AF13: 413.072 | AI13: 2850.462 | AJ13: 3142.442 | AK13: 3057.202 | AL13: 3180.489 | AM13: 3372.902 | AN13: 3459.629 | AO13: 3562.313 | AP13: 3642.53 | AQ13: 3044.802 | AR13: 3747.609 | AS13: 4328.94 | AT13: 4363.137 | AU13: 5256.148 | AV13: 4767.259 | AY13: 5105.816 | AZ13: 5736.273 | BA13: 5744.533 | BB13: 5928.91 | BC13: 6389.234 | BD13: 6603.184 | BE13: 7115.037 | BF13: 7400.068 | BG13: 5844.841 | BH13: 7240.434 | BI13: 9744.351 | BJ13: 9635.87 | BK13: 9960.103 | BL13: 9639.693 | BO13: 41030 | BP13: 41395 | BQ13: 41760 | BR13: 42125 | BS13: 42491 | BT13: 42856 | BU13: 43221 | BV13: 43586 | BW13: 43952 | BX13: 44317 | BY13: 44682 | BZ13: 45061 | CA13: 45413 | CB13: 45778 | CD13: Biennial (odd)
A14: Idaho | B14: ID | C14: 1295 | D14: 1313.41 | E14: 1403.03 | F14: 1488.58 | G14: 1606.15 | H14: 1666.778 | I14: 1853.19 | J14: 1954.259 | K14: 1875.391 | L14: 2089.445 | M14: 2553.109 | N14: 2162.795 | O14: 2601.192 | P14: 2689.056 | S14: 182.84 | T14: 194.06 | U14: 206.51 | V14: 212.48 | W14: 222.06 | X14: 215.894 | Y14: 234.96 | Z14: 256.323 | AA14: 293.003 | AB14: 260.889 | AC14: 324.08 | AD14: 872.563 | AE14: 751.932 | AF14: 979.247 | AI14: 1082.72 | AJ14: 1151.57 | AK14: 1233.41 | AL14: 1269.99 | AM14: 1345.13 | AN14: 1447.141 | AO14: 1546.05 | AP14: 1667.036 | AQ14: 1789.171 | AR14: 1866.354 | AS14: 2272.077 | AT14: 2077.893 | AU14: 1942.999 | AV14: 1940.004 | AY14: 2700.26 | AZ14: 2799.11 | BA14: 2987.77 | BB14: 3127.64 | BC14: 3340.37 | BD14: 3507.437 | BE14: 3823.13 | BF14: 4057.43 | BG14: 4148.572 | BH14: 4403.998 | BI14: 5464.071 | BJ14: 5547.111 | BK14: 5698.242 | BL14: 6077.619 | BO14: 40909 | BP14: 41275 | BQ14: 41640 | BR14: 42005 | BS14: 42370 | BT14: 42736 | BU14: 43101 | BV14: 43466 | BW14: 43831 | BX14: 44197 | BY14: 44562 | BZ14: 44927 | CA14: 45292 | CB14: 45658 | CD14: Annual
A15: Illinois | B15: IL | C15: =16879-1646 -> 15233 | D15: =17713-1727 -> 15986 | E15: =16717-1672 -> 15045 | F15: =14766-1477 -> 13289 | G15: =15354-1535 -> 13819 | H15: =15688-1569 -> 14119 | I15: =21071-2044 -> 19027 | J15: =22128-2157 -> 19971 | K15: =23643-2187 -> 21456 | L15: =23584-2181 -> 21403 | M15: =26687-2469 -> 24218 | N15: =29235-2704 -> 26531 | O15: =31254-2860 -> 28394 | P15: =33241-3042 -> 30199 | S15: =3070-430 -> 2640 | T15: =3391-475 -> 2916 | U15: =3267-457 -> 2810 | V15: =2700-446 -> 2254 | W15: =2648-410 -> 2238 | X15: =1900-333 -> 1567 | Y15: =2618-406 -> 2212 | Z15: =2890-426 -> 2464 | AA15: =3201-448 -> 2753 | AB15: =3240-486 -> 2754 | AC15: =5471-793 -> 4678 | AD15: =6832-956 -> 5876 | AE15: =6040-846 -> 5194 | AF15: =5969-836 -> 5133 | AI15: 7340 | AJ15: 7348 | AK15: 7842 | AL15: 8280 | AM15: 8203 | AN15: 8380 | AO15: 8491 | AP15: 9022 | AQ15: 9503 | AR15: 9486 | AS15: 10919 | AT15: 11897 | AU15: 11987 | AV15: 12039 | AY15: 32131 | AZ15: 33283 | BA15: 32747 | BB15: 30540 | BC15: 31012 | BD15: 30880 | BE15: 37593 | BF15: 39162 | BG15: 41634 | BH15: 41046 | BI15: 48245 | BJ15: 53397 | BK15: 55482 | BL15: 57718 | BO15: 40969 | BP15: 41306 | BQ15: 41699 | BR15: 42064 | BS15: 42430 | BT15: 42795 | BU15: 43160 | BV15: 43525 | BW15: 43891 | BX15: 44256 | BY15: 44621 | BZ15: 44986 | CA15: 45383 | CB15: 45717 | CD15: Annual
A16: Indiana | B16: IN | C16: 5084 | D16: 5162.7 | E16: 5279.6 | F16: 5121.8 | G16: 5372.1 | H16: 5661 | I16: 5922.9 | J16: 6174.1 | K16: 6395.5 | L16: 6710.6 | M16: 7578.9 | N16: 7907.4 | O16: 8283.6 | P16: 8861.5 | S16: 784.9 | T16: 900.3 | U16: 920.5 | V16: 984.7 | W16: 966.3 | X16: 949.2 | Y16: 870.7 | Z16: 850.9 | AA16: 872.4 | AB16: 883.8 | AC16: 1281.7 | AD16: 1358.4 | AE16: 1202.5 | AF16: 1304.2 | AI16: 6864.6 | AJ16: 7088.4 | AK16: 7242.9 | AL16: 7504.7 | AM16: 7665.3 | AN16: 7630.2 | AO16: 7837.9 | AP16: 8075.8 | AQ16: 8459.8 | AR16: 9074.4 | AS16: 9940.3 | AT16: 10815.2 | AU16: 10916.9 | AV16: 11092.6 | AY16: 14432 | AZ16: 14728.2 | BA16: 14858.7 | BB16: 14971.1 | BC16: 15343.3 | BD16: 15588.2 | BE16: 15961.6 | BF16: 16552 | BG16: 17259.9 | BH16: 18076.9 | BI16: 20279.7 | BJ16: 21854.1 | BK16: 22313.3 | BL16: 23192.4 | BO16: 40878 | BP16: 41365 | BQ16: 41609 | BR16: 42095 | BS16: 42339 | BT16: 42826 | BU16: 43070 | BV16: 43556 | BW16: 43800 | BX16: 44287 | BY16: 44531 | BZ16: 45017 | CA16: 45261 | CB16: 45627 | CD16: Biennial (odd)
A17: Iowa | B17: IA | C17: 3786.7 | D17: 4133.5 | E17: 4291.4 | F17: 4493.5 | G17: 4742.4 | H17: 4743.4 | I17: 4985.4 | J17: 4830.8 | K17: 5050.6 | L17: 5129.2 | M17: 5392.1 | N17: 5136.2 | O17: 5523.4 | P17: 4753.7 | S17: 511.3 | T17: 556.6 | U17: 610 | V17: 560.3 | W17: 531.8 | X17: 525.7 | Y17: 649 | Z17: 653 | AA17: 692.2 | AB17: 742.9 | AC17: 828.7 | AD17: 893.3 | AE17: 945.4 | AF17: 815.8 | AI17: 2538.3 | AJ17: 2676.1 | AK17: 2753 | AL17: 2891 | AM17: 2849.8 | AN17: 2980.8 | AO17: 3039.3 | AP17: 3316.1 | AQ17: 3342.1 | AR17: 3398.8 | AS17: 4002.6 | AT17: 3924.7 | AU17: 4361.3 | AV17: 4430.4 | AY17: 6280.6 | AZ17: 6870.6 | BA17: 6983.2 | BB17: 7175.5 | BC17: 7357.4 | BD17: 7364.5 | BE17: 7733.8 | BF17: 7848.4 | BG17: 8236.7 | BH17: 8385.6 | BI17: 9156.3 | BJ17: 9650.3 | BK17: 9697.8 | BL17: 8507.9 | BO17: 40969 | BP17: 41334 | BQ17: 41699 | BR17: 42064 | BS17: 42430 | BT17: 42795 | BU17: 43160 | BV17: 43525 | BW17: 43891 | BX17: 44274 | BY17: 44621 | BZ17: 44995 | CA17: 45352 | CB17: 45717 | CD17: Annual
A18: Kansas | B18: KS | C18: 2870.8 | D18: 2524.685 | E18: 2519.288 | F18: 2461.8 | G18: 2377 | H18: 2927 | I18: 3334.17 | J18: 3750 | K18: 3770 | L18: 3688.63 | M18: 4661.6 | N18: 4798.8 | O18: 4186.2 | P18: 4670.38 | S18: =270+26 -> 296 | T18: =370+31 -> 401 | U18: =425+37.45 -> 462.45 | V18: 489 | W18: 436 | X18: 316 | Y18: 394 | Z18: =450+42 -> 492 | AA18: =370+48 -> 418 | AB18: =282.52+48.7 -> 331.22 | AC18: =650+46 -> 696 | AD18: =1295.255+50 -> 1345.255 | AE18: =1561.5+45.2 -> 1606.7 | AF18: =1325+45 -> 1370 | AI18: =2225+350 -> 2575 | AJ18: =2087.5+320.7 -> 2408.2 | AK18: =2168.188+358.984 -> 2527.172 | AL18: 2786.2 | AM18: 2754.912 | AN18: 2667.317 | AO18: 2766.427 | AP18: =2344.993+440 -> 2784.993 | AQ18: =2320+450 -> 2770 | AR18: =2466.1+665.5 -> 3131.6 | AS18: 3413.9 | AT18: 3619.685 | AU18: 3417.9 | AV18: 3435 | AY18: 6174.32 | AZ18: 5885.526 | BA18: 5974.575 | BB18: 6325.033 | BC18: 6303.872 | BD18: 6705.497 | BE18: 7003.346 | BF18: 7431.693 | BG18: 7230.5 | BH18: 7561.94 | BI18: 8907 | BJ18: 10351.24 | BK18: 9791.6 | BL18: 10060.88 | BO18: 41061 | BP18: 41426 | BQ18: 41791 | BR18: 42186 | BS18: 42522 | BT18: 42887 | BU18: 43221 | BV18: 43586 | BW18: 43983 | BX18: 44348 | BY18: 44713 | BZ18: 45070 | CA18: 45444 | CB18: 45809 | CD18: Annual
A19: Kentucky | B19: KY | C19: 3563.5 | D19: 3689.4 | E19: 3977.3 | F19: 4135.8 | G19: 4411.1 | H19: 4588.6 | I19: 4649.5 | J19: 4793.2 | K19: 4813 | L19: 5004.1 | M19: 5342.26 | N19: 5249.29 | O19: 5548.1 | P19: 5742.1 | S19: 359.50547 | T19: 365.30454 | U19: 697.1 | V19: 687.5 | W19: =579.4+223.7 -> 803.1 | X19: =553.1+221.6 -> 774.7 | Y19: =600.6+200.2 -> 800.8 | Z19: =632.3+210.8 -> 843.1 | AA19: 547.5 | AB19: 469.1 | AC19: 909.75 | AD19: 963.75 | AE19: 1283.3 | AF19: 1313.4 | AI19: 3075.2 | AJ19: 3172.7 | AK19: 3149.6 | AL19: 3216.8 | AM19: 3539.8 | AN19: 3638.4 | AO19: 3699.4 | AP19: 3791.7 | AQ19: 4232.8 | AR19: 4336 | AS19: 5283.22 | AT19: 5625.42 | AU19: 6082.1 | AV19: 6315.9 | AY19: 9220.6 | AZ19: 9500.3 | BA19: 9794.3 | BB19: 10046.6 | BC19: 10617.2 | BD19: 10875.5 | BE19: 11005.9 | BF19: 11290 | BG19: 11704 | BH19: 11849.8 | BI19: 13758.988 | BJ19: 14154.399 | BK19: 15549.5 | BL19: 15654.9 | BO19: 40878 | BP19: 40878 | BQ19: 41609 | BR19: 41609 | BS19: 42339 | BT19: 42339 | BU19: 43070 | BV19: 43070 | BW19: 43800 | BX19: 43800 | BY19: 44531 | BZ19: 44531 | CA19: 45261 | CB19: 45261 | CD19: Biennial (even)
A20: Louisiana | B20: LA | C20: 2627.1 | D20: 2786.1 | E20: 2932.4 | F20: 2976.6 | G20: 3088.3 | H20: 3016.5 | I20: 3379.6 | J20: 3512.9 | K20: 3646.3 | L20: 3793.1 | M20: 4325.1 | N20: 4486.1 | O20: 4631.7 | P20: 3704.1 | S20: 155.9 | T20: 340 | U20: 350.8 | V20: 385 | W20: 510.4 | X20: 338.5 | Y20: 300 | Z20: 400 | AA20: 422.7 | AB20: 500 | AC20: 650 | AD20: 812.7 | AE20: 900 | AF20: 1152.6 | AI20: 2767.5 | AJ20: 2656.8 | AK20: 2695.7 | AL20: 2827.9 | AM20: 3774.5 | AN20: 3800.8 | AO20: 3108.4 | AP20: 3470.5 | AQ20: 3197.2 | AR20: 3404.5 | AS20: 4002.7 | AT20: 4432.8 | AU20: 4429.9 | AV20: 5405.1 | AY20: 9957.8 | AZ20: 10213.8 | BA20: 10640.4 | BB20: 10545.8 | BC20: 12032.1 | BD20: 11981 | BE20: 11467.5 | BF20: 12354.4 | BG20: 11518.2 | BH20: 12296.3 | BI20: 13837.2 | BJ20: 15277.4 | BK20: 15778.8 | BL20: 15841.5 | BO20: 41030 | BP20: 41395 | BQ20: 41760 | BR20: 42125 | BS20: 42522 | BT20: 42856 | BU20: 43191 | BV20: 43556 | BW20: 43952 | BX20: 44317 | BY20: 44682 | BZ20: 45064 | CA20: 45413 | CB20: 45778 | CD20: Annual
